At time 0 process 1 arrived arr 0 total 7 remain 7 wait 0
At time 0 process 2 arrived arr 0 total 2 remain 2 wait 0
At time 0 process 1 resumed arr 0 total 7 remain 7 wait 0
At time 1 process 3 arrived arr 1 total 1 remain 1 wait 0
At time 2 process 4 arrived arr 2 total 4 remain 4 wait 0
At time 3 process 1 stopped arr 0 total 7 remain 4 wait 0
At time 3 process 5 arrived arr 3 total 3 remain 3 wait 0
At time 3 process 2 resumed arr 0 total 2 remain 2 wait 3
At time 4 process 6 arrived arr 4 total 2 remain 2 wait 0
At time 5 process 2 finished arr 0 total 2 remain 0 wait 3 TA 5 WTA 2.50
At time 5 process 7 arrived arr 5 total 1 remain 1 wait 0
At time 5 process 3 resumed arr 1 total 1 remain 1 wait 4
At time 6 process 3 finished arr 1 total 1 remain 0 wait 4 TA 5 WTA 5.00
At time 6 process 8 arrived arr 6 total 5 remain 5 wait 0
At time 6 process 9 arrived arr 6 total 3 remain 3 wait 0
At time 6 process 4 resumed arr 2 total 4 remain 4 wait 4
At time 7 process 10 arrived arr 7 total 2 remain 2 wait 0
At time 9 process 4 stopped arr 2 total 4 remain 1 wait 4
At time 9 process 1 resumed arr 0 total 7 remain 4 wait 6
At time 9 process 1 resumed arr 0 total 7 remain 4 wait 6
At time 12 process 1 stopped arr 0 total 7 remain 1 wait 6
At time 12 process 5 resumed arr 3 total 3 remain 3 wait 9
At time 15 process 5 finished arr 3 total 3 remain 0 wait 9 TA 12 WTA 4.00
At time 15 process 6 resumed arr 4 total 2 remain 2 wait 11
At time 17 process 6 finished arr 4 total 2 remain 0 wait 11 TA 13 WTA 6.50
At time 17 process 7 resumed arr 5 total 1 remain 1 wait 12
At time 18 process 7 finished arr 5 total 1 remain 0 wait 12 TA 13 WTA 13.00
At time 18 process 8 resumed arr 6 total 5 remain 5 wait 12
At time 21 process 8 stopped arr 6 total 5 remain 2 wait 12
At time 21 process 9 resumed arr 6 total 3 remain 3 wait 15
At time 24 process 9 finished arr 6 total 3 remain 0 wait 15 TA 18 WTA 6.00
At time 24 process 10 resumed arr 7 total 2 remain 2 wait 17
At time 26 process 10 finished arr 7 total 2 remain 0 wait 17 TA 19 WTA 9.50
At time 26 process 4 resumed arr 2 total 4 remain 1 wait 21
At time 26 process 4 resumed arr 2 total 4 remain 1 wait 21
At time 27 process 4 finished arr 2 total 4 remain 0 wait 21 TA 25 WTA 6.25
At time 27 process 1 resumed arr 0 total 7 remain 1 wait 21
At time 27 process 1 resumed arr 0 total 7 remain 1 wait 21
At time 28 process 1 finished arr 0 total 7 remain 0 wait 21 TA 28 WTA 4.00
At time 28 process 8 resumed arr 6 total 5 remain 2 wait 19
At time 28 process 8 resumed arr 6 total 5 remain 2 wait 19
